<?xml version="1.0" encoding="utf-8"?>

<robot name="arm_upper" xmlns:xacro="http://ros.org/wiki/xacro">

  <!-- Define a number of dimensions using properties -->
  <property name="arm_upper_offset_x" value="0.06" />
  <property name="arm_upper_offset_y" value="0.0" />
  <property name="arm_upper_offset_z" value="0.1" />
  <property name="arm_upper_radius" value="0.009" />
  <property name="arm_upper_length" value="0.4" />
     
  <!-- Define the upper arm -->
  <macro name="arm_upper" params="parent name">
    <joint name="shoulder_joint" type="revolute">
      <origin xyz="${arm_upper_offset_x} ${arm_upper_offset_y} ${arm_upper_offset_z}" rpy="0 0 0" />
      <axis xyz="0 1 0"/>
      <limit effort="1.0" lower="${-M_PI/2}" upper="0" velocity="1.571"/>
      <parent link="torso_upper_link"/>
      <child link="arm_upper_link"/>
    </joint>
    <link name="arm_upper_link">
      <inertial>
        <mass value="0.5" />
        <origin xyz="0 0 0" />
        <inertia ixx="1.0" ixy="0.0" ixz="0.0"
                 iyy="1.0" iyz="0.0"
                 izz="1.0" />
      </inertial>

      <visual>
        <!-- <origin xyz="-0.01 0 -0.39" rpy="0 ${87.5*M_PI/180} 0" /> -->
	<origin xyz="-0.145 -0.136  -0.725" rpy="${-2*M_PI/180} 0 ${M_PI/2}" />
	<geometry>
	  <mesh filename="package://mini_description/meshes/mini1.5/mini2_arm_upper_module.dae" scale="${mesh_scale} ${mesh_scale} ${mesh_scale}" />
	</geometry>
	<!-- <material color="yellow"/> -->
      </visual>
      <collision>
        <origin xyz="0 0 -0.24" rpy="0 0 0" />
        <geometry>
	  <cylinder length="${arm_upper_length}" radius="${arm_upper_radius}" />
        </geometry>
       </collision> 
    </link>
  </macro>

</robot>
